
try {
    let a =  b + 2;
} catch (error) {
    console.log(error);
}

console.log("Teste");

// o try catch executa o codigo e se haver erro ele so para o codigo dentro dele e o resto do codigo funciona normalmente.